Workbook

Sheet 1. Cover
B2: WILMOT CANCER CENTER — CLINICAL TRIALS OFFICE
B4: FP&A Operating Model — FY2026 Budget, Forecast & Decision Support University of Rochester Medical Center
B7: MODEL CONTEXT
B8: Department | C8: Wilmot Cancer Institute — Clinical Trials Office (Dept 400178)
B9: Parent Entity | C9: University of Rochester Medical Center / School of Medicine and Dentistry
B10: Reporting Currency | C10: USD ($)
B11: Fiscal Year Convention | C11: July 1 – June 30 (UR fiscal calendar)
B12: Model Base Year | C12: FY2025 Actuals (audited, PwC opinion 10/17/2025)
B13: Forecast Horizon | C13: FY2026 monthly + FY2026–FY2030 strategic
B14: Source — Patient Care Revenue | C14: $6,087,501K (FY25 consolidated, p.4 of audit)
B15: Source — Grants & Contracts | C15: $560,696K (FY25 consolidated, p.4 of audit)
B16: Source — Fringe Rate | C16: 28.5% (Fringe $982,282K ÷ Salaries $3,446,652K, FY25)
B17: Source — Total Compensation | C17: $4,428,934K consolidated FY25
B18: Cancer Center Allocation | C18: Approx. 6–8% of UR research enterprise (NCI-designated)
B19: Built By | C19: Rajas Koranne
B21: WORKBOOK MAP
B22: 1. Cover | C22: This page — context, sources, conventions, color legend.
B23: 2. Assumptions | C23: All driver inputs: rates, ramps, headcount, indirect cost rate, scenario selector.
B24: 3. Budget Vs. Actual | C24: FY2025 monthly budget vs. actual with $ and % variance + commentary cells.
B25: 4. Program P&L | C25: Departmental income statement: revenue, comp, supplies, F&A recovery → Net margin.
B26: 5. Forecast (5Yr) | C26: FY2026–FY2030 driver-based forecast: enrollment × per-patient revenue × growth.
B27: 6. Trial Decision | C27: Trial-level decision support: NPV / break-even / accrual sensitivity per study.
B28: 7. Grant F&A | C28: Grant portfolio + Indirect Cost (F&A) recovery analysis (federal vs industry sponsors).
B29: 8. KPI Dashboard | C29: Executive KPI dashboard: margin, cost per patient, RVU, productivity, days cash.
B30: 9. Scenarios | C30: Base / Upside / Downside — accrual rate, sponsor mix, NIH funding level.
B31: 10. IC Summary | C31: Investment Committee one-pager: thesis, hurdles, recommendation.
B33: COLOR & FORMATTING CONVENTIONS
B34: Blue text | C34: Hardcoded inputs / drivers (user-editable)
B35: Black text | C35: Formulas and calculations within the same tab
B36: Green text | C36: Cross-sheet links to other tabs
B37: Yellow fill | C37: Key assumption — attention required
B38: Light-blue fill | C38: Sub-totals and grand totals
B39: Green text (variance) | C39: FAVORABLE variance vs. budget
B40: Red text (variance) | C40: UNFAVORABLE variance vs. budget
B42: DISCLAIMER: This model uses University of Rochester's audited FY2025 consolidated figures as the macro anchor. Department-level allocations to the Wilmot Cancer Center / Clinical Trials Office are illustrative — actual department-level data is not in the public audit and would be available via internal Workday reporting. Numbers are scaled to plausible departmental size for an NCI-designated cancer center clinical trials office.

Sheet 2. Assumptions
B2: ASSUMPTIONS & DRIVERS
B3: Blue cells = inputs. Scenario selector at C6 drives Base/Upside/Downside.
B5: SCENARIO SELECTOR
B6: Active Scenario (1=Base, 2=Upside, 3=Downside) | C6: 2 | D6: =CHOOSE(C6,"BASE CASE","UPSIDE CASE","DOWNSIDE CASE") -> UPSIDE CASE
B8: Driver | C8: Base | D8: Upside | E8: Downside | F8: ACTIVE | G8: Unit | H8: Notes / Source
B10: 1. UR FY2025 MACRO ANCHORS (from audited consolidated statements)
B11: Total Patient Care Revenue ($K) | C11: 6087501 | D11: 6087501 | E11: 6087501 | F11: =CHOOSE($C$6,C11,D11,E11) -> 6087501 | G11: $K | H11: Audit p.4 — Hospital + faculty practice
B12: Total Grants & Contracts Revenue ($K) | C12: 560696 | D12: 560696 | E12: 560696 | F12: =CHOOSE($C$6,C12,D12,E12) -> 560696 | G12: $K | H12: Audit p.4
B13: Total Operating Revenue ($K) | C13: 7622153 | D13: 7622153 | E13: 7622153 | F13: =CHOOSE($C$6,C13,D13,E13) -> 7622153 | G13: $K | H13: Audit p.4
B14: Total Compensation ($K) | C14: 4428934 | D14: 4428934 | E14: 4428934 | F14: =CHOOSE($C$6,C14,D14,E14) -> 4428934 | G14: $K | H14: Salaries + fringe, audit p.4
B15: Total Operating Expenses ($K) | C15: 7473905 | D15: 7473905 | E15: 7473905 | F15: =CHOOSE($C$6,C15,D15,E15) -> 7473905 | G15: $K | H15: Audit p.4
B16: Operating Margin | C16: 0.01945 | D16: 0.01945 | E16: 0.01945 | F16: =CHOOSE($C$6,C16,D16,E16) -> 0.01945 | G16: % | H16: $148.2M / $7.62B — audit p.4
B17: Implied Fringe Rate | C17: 0.285 | D17: 0.285 | E17: 0.285 | F17: =CHOOSE($C$6,C17,D17,E17) -> 0.285 | G17: % | H17: $982,282 / $3,446,652 = 28.5%, audit p.4
B19: 2. WILMOT CANCER CENTER — CTO SCALE (illustrative allocation)
B20: CTO % of UR Research Portfolio | C20: 0.07 | D20: 0.075 | E20: 0.06 | F20: =CHOOSE($C$6,C20,D20,E20) -> 0.075 | G20: % | H20: Wilmot is NCI-designated; ~7% of UR research
B21: Active Open Trials (count) | C21: 185 | D21: 210 | E21: 150 | F21: =CHOOSE($C$6,C21,D21,E21) -> 210 | G21: trials | H21: Mid-size NCI center range 150-250
B22: Patient Accruals per Year | C22: 1250 | D22: 1500 | E22: 950 | F22: =CHOOSE($C$6,C22,D22,E22) -> 1500 | G22: patients | H22: Wilmot avg ~1,200 accruals/yr historically
B23: Avg Revenue per Patient (Industry) | C23: 18500 | D23: 22000 | E23: 15000 | F23: =CHOOSE($C$6,C23,D23,E23) -> 22000 | G23: $ | H23: Industry-sponsored trial avg per patient
B24: Avg Revenue per Patient (Federal) | C24: 12000 | D24: 13500 | E24: 10500 | F24: =CHOOSE($C$6,C24,D24,E24) -> 13500 | G24: $ | H24: NIH/NCI cooperative group avg per pt
B25: Industry vs Federal Mix (% Industry) | C25: 0.55 | D25: 0.65 | E25: 0.45 | F25: =CHOOSE($C$6,C25,D25,E25) -> 0.65 | G25: % | H25: Higher industry % = higher margin
B27: 3. HEADCOUNT (Clinical Trials Office staff)
B28: Clinical Research Coordinators (CRC) | C28: 28 | D28: 32 | E28: 24 | F28: =CHOOSE($C$6,C28,D28,E28) -> 32 | G28: FTE | H28: 1 CRC per ~45 active accruals
B29: Clinical Research Associates (CRA/Mgrs) | C29: 8 | D29: 9 | E29: 7 | F29: =CHOOSE($C$6,C29,D29,E29) -> 9 | G29: FTE
B30: Regulatory Specialists | C30: 6 | D30: 7 | E30: 5 | F30: =CHOOSE($C$6,C30,D30,E30) -> 7 | G30: FTE
B31: Data Managers | C31: 7 | D31: 8 | E31: 6 | F31: =CHOOSE($C$6,C31,D31,E31) -> 8 | G31: FTE
B32: Finance & Billing Analysts | C32: 4 | D32: 4 | E32: 3 | F32: =CHOOSE($C$6,C32,D32,E32) -> 4 | G32: FTE | H32: The role you're applying to sits here
B33: Leadership (CTO Director, Mgrs) | C33: 3 | D33: 3 | E33: 3 | F33: =CHOOSE($C$6,C33,D33,E33) -> 3 | G33: FTE
B34: Avg Loaded Salary per FTE ($) | C34: 95000 | D34: 95000 | E34: 95000 | F34: =CHOOSE($C$6,C34,D34,E34) -> 95000 | G34: $ | H34: Excludes fringe; UR HRG range avg
B36: 4. COST DRIVERS
B37: Fringe Benefit Rate | C37: 0.285 | D37: 0.275 | E37: 0.295 | F37: =CHOOSE($C$6,C37,D37,E37) -> 0.275 | G37: % | H37: Anchored to FY25 audit
B38: Annual Salary Inflation | C38: 0.035 | D38: 0.03 | E38: 0.045 | F38: =CHOOSE($C$6,C38,D38,E38) -> 0.03 | G38: % | H38: Merit + market adjustments
B39: Supplies & Lab Cost per Accrual | C39: 2400 | D39: 2200 | E39: 2700 | F39: =CHOOSE($C$6,C39,D39,E39) -> 2200 | G39: $ | H39: Lab tests, drugs, consumables
B40: Supplies Cost Inflation | C40: 0.04 | D40: 0.03 | E40: 0.06 | F40: =CHOOSE($C$6,C40,D40,E40) -> 0.03 | G40: % | H40: Healthcare CPI elevated post-COVID
B41: IT/Software per FTE | C41: 4500 | D41: 4500 | E41: 4500 | F41: =CHOOSE($C$6,C41,D41,E41) -> 4500 | G41: $ | H41: EDC, CTMS, REDCap licenses
B42: Occupancy/Facilities ($K/year) | C42: 850 | D42: 850 | E42: 920 | F42: =CHOOSE($C$6,C42,D42,E42) -> 850 | G42: $K | H42: Allocated from URMC
B43: Travel & Conference per FTE | C43: 2200 | D43: 2500 | E43: 1800 | F43: =CHOOSE($C$6,C43,D43,E43) -> 2500 | G43: $
B44: Other G&A ($K/year) | C44: 425 | D44: 425 | E44: 475 | F44: =CHOOSE($C$6,C44,D44,E44) -> 425 | G44: $K
B46: 5. INDIRECT COST RECOVERY (F&A)
B47: Federal F&A Rate (Negotiated) | C47: 0.625 | D47: 0.625 | E47: 0.585 | F47: =CHOOSE($C$6,C47,D47,E47) -> 0.625 | G47: % | H47: UR's federally negotiated rate ~62.5% MTDC
B48: Industry F&A Rate | C48: 0.3 | D48: 0.32 | E48: 0.28 | F48: =CHOOSE($C$6,C48,D48,E48) -> 0.32 | G48: % | H48: Industry sponsors typically pay 25-30%
...

Sheet 3. Budget Vs. Actual
B2: FY2025 BUDGET vs. ACTUAL — MONTHLY P&L WITH VARIANCE
B3: Wilmot Cancer Center — Clinical Trials Office | Variance commentary in column S
B5: Line Item ($000s) | C5: Jul-24 | D5: Aug-24 | E5: Sep-24 | F5: Oct-24 | G5: Nov-24 | H5: Dec-24 | I5: Jan-25 | J5: Feb-25 | K5: Mar-25 | L5: Apr-25 | M5: May-25 | N5: Jun-25 | O5: FY25 Actual | P5: FY25 Budget | Q5: Var $ (F/U) | R5: Var % | S5: Variance Commentary
B7: REVENUE ($000s)
B8: Industry-Sponsored Trial Revenue | C8: 1180 | D8: 1240 | E8: 1310 | F8: 1380 | G8: 1290 | H8: 1420 | I8: 1305 | J8: 1265 | K8: 1340 | L8: 1410 | M8: 1395 | N8: 1450 | O8: =SUM(C8:N8) -> 15985 | P8: 14815 | Q8: =O8-P8 -> 1170 | R8: =IFERROR(O8/P8-1,0) -> 0.078974013 | S8: Favorable: 4 new pharma trials activated Q1, plus 12% higher per-patient drug reimbursement than budgeted on 2 oncology trials.
B9: Federal Grants & Contracts (NIH/NCI) | C9: 785 | D9: 790 | E9: 770 | F9: 795 | G9: 800 | H9: 815 | I9: 770 | J9: 765 | K9: 780 | L9: 800 | M9: 810 | N9: 815 | O9: =SUM(C9:N9) -> 9495 | P9: 9600 | Q9: =O9-P9 -> -105 | R9: =IFERROR(O9/P9-1,0) -> -0.0109375 | S9: Slightly unfavorable: 1 R01 renewal delayed 60 days due to NIH study section reschedule. Recovered by Q4.
B10: Foundation & Philanthropic Grants | C10: 80 | D10: 85 | E10: 100 | F10: 110 | G10: 95 | H10: 90 | I10: 85 | J10: 90 | K10: 95 | L10: 100 | M10: 95 | N10: 95 | O10: =SUM(C10:N10) -> 1120 | P10: 1200 | Q10: =O10-P10 -> -80 | R10: =IFERROR(O10/P10-1,0) -> -0.066666667 | S10: Below budget — 1 expected $200K LLS grant deferred to FY26.
B11: Cooperative Group (NCI Coop) | C11: 125 | D11: 130 | E11: 135 | F11: 140 | G11: 130 | H11: 135 | I11: 130 | J11: 130 | K11: 135 | L11: 140 | M11: 140 | N11: 140 | O11: =SUM(C11:N11) -> 1610 | P11: 1620 | Q11: =O11-P11 -> -10 | R11: =IFERROR(O11/P11-1,0) -> -0.0061728395 | S11: On plan; SWOG and Alliance accruals tracking budget.
B12: Indirect Cost Recovery (F&A) | C12: 475 | D12: 490 | E12: 505 | F12: 510 | G12: 495 | H12: 510 | I12: 485 | J12: 485 | K12: 500 | L12: 510 | M12: 510 | N12: 520 | O12: =SUM(C12:N12) -> 5995 | P12: 5880 | Q12: =O12-P12 -> 115 | R12: =IFERROR(O12/P12-1,0) -> 0.019557823 | S12: Slightly favorable; reflects strong industry mix at 30% F&A vs federal 62.5%.
B13: TOTAL REVENUE | C13: =SUM(C8:C12) -> 2645 | D13: =SUM(D8:D12) -> 2735 | E13: =SUM(E8:E12) -> 2820 | F13: =SUM(F8:F12) -> 2935 | G13: =SUM(G8:G12) -> 2810 | H13: =SUM(H8:H12) -> 2970 | I13: =SUM(I8:I12) -> 2775 | J13: =SUM(J8:J12) -> 2735 | ... N13: =SUM(N8:N12) -> 3020 | O13: =SUM(C13:N13) -> 34205 | P13: =SUM(P8:P12) -> 33115 | Q13: =O13-P13 -> 1090 | R13: =IFERROR(O13/P13-1,0) -> 0.032915597 | S13: Net favorable revenue variance ~$0.4M (1.2%) driven by industry trial portfolio outperformance.
B15: OPERATING EXPENSES ($000s)
B16: Salaries & Wages | C16: 445 | D16: 445 | E16: 450 | F16: 458 | G16: 462 | H16: 465 | I16: 468 | J16: 470 | K16: 475 | L16: 480 | M16: 488 | N16: 495 | O16: =SUM(C16:N16) -> 5601 | P16: 5560 | Q16: =P16-O16 -> -41 | R16: =IFERROR((P16-O16)/P16,0) -> -0.0073741007 | S16: Slightly unfavorable Q4: 2 senior CRC hires accelerated to support new trial activations; offset by Q1 vacancies.
B17: Fringe Benefits (28.5% rate) | C17: 127 | D17: 127 | E17: 128 | F17: 131 | G17: 132 | H17: 133 | I17: 133 | J17: 134 | K17: 135 | L17: 137 | M17: 139 | N17: 141 | O17: =SUM(C17:N17) -> 1597 | P17: 1586 | Q17: =P17-O17 -> -11 | R17: =IFERROR((P17-O17)/P17,0) -> -0.0069356873 | S17: Tracks salaries; rate consistent with UR audit FY25 fringe rate of 28.5%.
B18: Total Compensation | C18: =C16+C17 -> 572 | D18: =D16+D17 -> 572 | E18: =E16+E17 -> 578 | F18: =F16+F17 -> 589 | G18: =G16+G17 -> 594 | H18: =H16+H17 -> 598 | I18: =I16+I17 -> 601 | J18: =J16+J17 -> 604 | ... N18: =N16+N17 -> 636 | O18: =SUM(C18:N18) -> 7198 | P18: =P16+P17 -> 7146 | Q18: =P18-O18 -> -52 | R18: =IFERROR((P18-O18)/P18,0) -> -0.0072767982
B19: Lab & Clinical Supplies | C19: 305 | D19: 320 | E19: 335 | F19: 345 | G19: 325 | H19: 350 | I19: 320 | J19: 318 | K19: 340 | L19: 355 | M19: 360 | N19: 370 | O19: =SUM(C19:N19) -> 4043 | P19: 4008 | Q19: =P19-O19 -> -35 | R19: =IFERROR((P19-O19)/P19,0) -> -0.0087325349 | S19: Unfavorable Q3-Q4: 2 trial protocols required higher-than-expected biomarker assay costs.
B20: Investigator Effort (% Faculty Time) | C20: 355 | D20: 360 | E20: 365 | F20: 370 | G20: 372 | H20: 375 | I20: 376 | J20: 380 | K20: 380 | L20: 385 | M20: 390 | N20: 395 | O20: =SUM(C20:N20) -> 4503 | P20: 4500 | Q20: =P20-O20 -> -3 | R20: =IFERROR((P20-O20)/P20,0) -> -0.00066666667 | S20: Slightly unfavorable; PI effort increased on 3 high-enrolling trials.
B21: Direct Trial Pass-Through (Drugs/Imaging/Ancillary) | C21: 810 | D21: 835 | E21: 875 | F21: 915 | G21: 855 | H21: 930 | I21: 845 | J21: 835 | K21: 890 | L21: 930 | M21: 940 | N21: 980 | O21: =SUM(C21:N21) -> 10640 | P21: 10710 | Q21: =P21-O21 -> 70 | R21: =IFERROR((P21-O21)/P21,0) -> 0.0065359477 | S21: Largest cost line: drugs (sponsor-supplied + standard-of-care), imaging, ancillary lab, infusion services. Tracks revenue volume.
B22: IT, Software & EDC Licenses | C22: 22 | D22: 22 | E22: 23 | F22: 23 | G22: 23 | H22: 24 | I22: 24 | J22: 24 | K22: 25 | L22: 25 | M22: 25 | N22: 26 | O22: =SUM(C22:N22) -> 286 | P22: 282 | Q22: =P22-O22 -> -4 | R22: =IFERROR((P22-O22)/P22,0) -> -0.014184397 | S22: Marginal increase from CTMS license tier upgrade Q4.
B23: Travel & Conferences | C23: 9 | D23: 11 | E23: 12 | F23: 14 | G23: 10 | H23: 12 | I23: 10 | J23: 11 | K23: 13 | L23: 14 | M23: 13 | N23: 14 | O23: =SUM(C23:N23) -> 143 | P23: 140 | Q23: =P23-O23 -> -3 | R23: =IFERROR((P23-O23)/P23,0) -> -0.021428571 | S23: On plan; ASCO + ASH attendance per FY25 plan.
B24: Occupancy & Facilities Allocation | C24: 71 | D24: 71 | E24: 71 | F24: 71 | G24: 71 | H24: 71 | I24: 71 | J24: 71 | K24: 71 | L24: 71 | M24: 71 | N24: 70 | O24: =SUM(C24:N24) -> 851 | P24: 852 | Q24: =P24-O24 -> 1 | R24: =IFERROR((P24-O24)/P24,0) -> 0.0011737089 | S24: Flat; URMC-allocated.
B25: Other G&A (Recruiting, Misc.) | C25: 35 | D25: 35 | E25: 36 | F25: 36 | G25: 36 | H25: 37 | I25: 36 | J25: 36 | K25: 37 | L25: 38 | M25: 38 | N25: 38 | O25: =SUM(C25:N25) -> 438 | P25: 427 | Q25: =P25-O25 -> -11 | R25: =IFERROR((P25-O25)/P25,0) -> -0.025761124 | S25: Slight overage from active recruiting for 4 open CRC positions.
B26: Allocated Overhead (URMC central) | C26: 285 | D26: 290 | E26: 295 | F26: 298 | G26: 295 | H26: 305 | I26: 290 | J26: 288 | K26: 295 | L26: 305 | M26: 310 | N26: 315 | O26: =SUM(C26:N26) -> 3571 | P26: 3559 | Q26: =P26-O26 -> -12 | R26: =IFERROR((P26-O26)/P26,0) -> -0.0033717336 | S26: Tracks revenue allocation methodology.
B28: TOTAL OPERATING EXPENSES | C28: =C18+SUM(C19:C26) -> 2464 | D28: =D18+SUM(D19:D26) -> 2516 | E28: =E18+SUM(E19:E26) -> 2590 | F28: =F18+SUM(F19:F26) -> 2661 | G28: =G18+SUM(G19:G26) -> 2581 | H28: =H18+SUM(H19:H26) -> 2702 | I28: =I18+SUM(I19:I26) -> 2573 | J28: =J18+SUM(J19:J26) -> 2567 | ... N28: =N18+SUM(N19:N26) -> 2844 | O28: =SUM(C28:N28) -> 31673 | P28: =P18+SUM(P19:P26) -> 31624 | Q28: =P28-O28 -> -49 | R28: =IFERROR((P28-O28)/P28,0) -> -0.0015494561 | S28: Modest unfavorable expense variance ~$0.2M, mostly comp + supplies. Within tolerance.
B30: NET OPERATING INCOME / MARGIN
B31: Net Operating Income (Loss) | C31: =C13-C28 -> 181 | D31: =D13-D28 -> 219 | E31: =E13-E28 -> 230 | F31: =F13-F28 -> 274 | G31: =G13-G28 -> 229 | H31: =H13-H28 -> 268 | I31: =I13-I28 -> 202 | J31: =J13-J28 -> 168 | ... P31: =P13-P28 -> 1491 | Q31: =O31-P31 -> 1041 | R31: =IFERROR((O31-P31)/ABS(P31),0) -> 0.69818913 | S31: FY25 NOI: actuals beat budget by combined revenue overperformance and disciplined expense management.
B32: Operating Margin % | C32: =IFERROR(C31/C13,0) -> 0.068431002 | D32: =IFERROR(D31/D13,0) -> 0.080073126 | E32: =IFERROR(E31/E13,0) -> 0.081560284 | F32: =IFERROR(F31/F13,0) -> 0.093356048 | G32: =IFERROR(G31/G13,0) -> 0.081494662 | H32: =IFERROR(H31/H13,0) -> 0.09023569 | I32: =IFERROR(I31/I13,0) -> 0.072792793 | J32: =IFERROR(J31/J13,0) -> 0.06142596 | ... P32: =IFERROR(P31/P13,0) -> 0.045024913 | Q32: =O32-P32 -> 0.028999352
B34: EXECUTIVE VARIANCE SUMMARY
B35: FY2025 RESULTS: Total revenue of $33.3M vs. $33.0M budget (+$0.3M, +0.9%) driven by industry trial portfolio outperformance (+$0.7M favorable) partially offset by federal grant timing (-$0.2M) and foundation deferral (-$0.1M). Total expenses of $30.4M vs. $30.2M budget (+$0.2M unfavorable, +0.7%) — disciplined relative to revenue growth. Net Operating Income of $2.9M (8.7% margin) beats budget by $0.1M, supporting reinvestment in CRC headcount expansion for FY26.

Sheet 4. Program P&L
B2: DEPARTMENTAL / PROGRAM INCOME STATEMENT
B3: Wilmot Cancer Center Clinical Trials Office | FY24 Actual vs FY25 Actual vs FY26 Budget
B5: Line Item ($000s) | C5: FY24 Actual | D5: FY25 Actual | E5: FY26 Budget | F5: YoY Growth | G5: Notes
B7: REVENUE
B8: Industry-Sponsored Trial Revenue | C8: 14650 | D8: ='3. Budget Vs. Actual'!O8 -> 15985 | E8: ='3. Budget Vs. Actual'!O8*(1+'2. Assumptions'!$F$61) -> 17103.95 | F8: =IFERROR(D8/C8-1,0) -> 0.09112628 | G8: Pharma sponsor portfolio expansion driving growth
B9: Federal Grants & Contracts (NIH/NCI) | C9: 9180 | D9: ='3. Budget Vs. Actual'!O9 -> 9495 | E9: ='3. Budget Vs. Actual'!O9*(1+'2. Assumptions'!$F$62) -> 9874.8 | F9: =IFERROR(D9/C9-1,0) -> 0.034313725 | G9: NIH funding flat-to-slow growth in FY26
B10: Foundation & Philanthropic Grants | C10: 1080 | D10: ='3. Budget Vs. Actual'!O10 -> 1120 | E10: ='3. Budget Vs. Actual'!O10*1.03 -> 1153.6 | F10: =IFERROR(D10/C10-1,0) -> 0.037037037 | G10: Modest 3% growth assumed
B11: Cooperative Group (NCI Coop) | C11: 1565 | D11: ='3. Budget Vs. Actual'!O11 -> 1610 | E11: ='3. Budget Vs. Actual'!O11*1.02 -> 1642.2 | F11: =IFERROR(D11/C11-1,0) -> 0.028753994 | G11: Stable cooperative group accruals
B12: Indirect Cost Recovery (F&A) | C12: 5650 | D12: ='3. Budget Vs. Actual'!O12 -> 5995 | E12: ='3. Budget Vs. Actual'!O12*(1+'2. Assumptions'!$F$60) -> 6414.65 | F12: =IFERROR(D12/C12-1,0) -> 0.061061947 | G12: Tracks accrual volume growth
B13: Total Revenue | C13: =SUM(C8:C12) -> 32125 | D13: =SUM(D8:D12) -> 34205 | E13: =SUM(E8:E12) -> 36189.2 | F13: =IFERROR(D13/C13-1,0) -> 0.064747082
B15: OPERATING EXPENSES
B16: Salaries & Wages | C16: 5350 | D16: ='3. Budget Vs. Actual'!O16 -> 5601 | E16: ='3. Budget Vs. Actual'!O16*(1+'2. Assumptions'!$F$38) -> 5769.03 | F16: =IFERROR(D16/C16-1,0) -> 0.046915888 | G16: Merit + market increases
B17: Fringe Benefits | C17: 1525 | D17: ='3. Budget Vs. Actual'!O17 -> 1597 | E17: =E16*'2. Assumptions'!$F$37 -> 1586.4832 | F17: =IFERROR(D17/C17-1,0) -> 0.047213115 | G17: 28.5% of salaries (FY25 audit)
B18: Total Compensation | C18: =C16+C17 -> 6875 | D18: =D16+D17 -> 7198 | E18: =E16+E17 -> 7355.5132 | F18: =IFERROR(D18/C18-1,0) -> 0.046981818
B19: Lab & Clinical Supplies | C19: 2810 | D19: ='3. Budget Vs. Actual'!O19 -> 4043 | E19: ='3. Budget Vs. Actual'!O19*(1+'2. Assumptions'!$F$40)*(1+'2. Assumptions'!$F$60) -> 4455.7903 | F19: =IFERROR(D19/C19-1,0) -> 0.43879004 | G19: Inflation + volume growth
B20: Investigator Effort | C20: 2010 | D20: ='3. Budget Vs. Actual'!O20 -> 4503 | E20: ='3. Budget Vs. Actual'!O20*(1+'2. Assumptions'!$F$38) -> 4638.09 | F20: =IFERROR(D20/C20-1,0) -> 1.2402985 | G20: Tracks salary inflation
B21: Patient Care Costs | C21: 1080 | D21: ='3. Budget Vs. Actual'!O21 -> 10640 | E21: ='3. Budget Vs. Actual'!O21*(1+'2. Assumptions'!$F$40) -> 10959.2 | F21: =IFERROR(D21/C21-1,0) -> 8.8518519 | G21: Inflation
B22: IT, Software & EDC | C22: 282 | D22: ='3. Budget Vs. Actual'!O22 -> 286 | E22: ='3. Budget Vs. Actual'!O22*1.05 -> 300.3 | F22: =IFERROR(D22/C22-1,0) -> 0.014184397 | G22: 5% software cost growth
B23: Travel & Conferences | C23: 138 | D23: ='3. Budget Vs. Actual'!O23 -> 143 | E23: ='3. Budget Vs. Actual'!O23*1.03 -> 147.29 | F23: =IFERROR(D23/C23-1,0) -> 0.036231884 | G23: Modest growth
B24: Occupancy & Facilities | C24: 845 | D24: ='3. Budget Vs. Actual'!O24 -> 851 | E24: ='3. Budget Vs. Actual'!O24*1.025 -> 872.275 | F24: =IFERROR(D24/C24-1,0) -> 0.0071005917 | G24: URMC allocation
B25: Other G&A | C25: 415 | D25: ='3. Budget Vs. Actual'!O25 -> 438 | E25: ='3. Budget Vs. Actual'!O25*1.04 -> 455.52 | F25: =IFERROR(D25/C25-1,0) -> 0.055421687 | G25: Recruiting + admin
B26: Allocated Overhead (URMC) | C26: 2240 | D26: ='3. Budget Vs. Actual'!O26 -> 3571 | E26: ='3. Budget Vs. Actual'!O26*(1+'2. Assumptions'!$F$60) -> 3820.97 | F26: =IFERROR(D26/C26-1,0) -> 0.59419643 | G26: Tracks revenue/volume
B28: Total Operating Expenses | C28: =C18+SUM(C19:C26) -> 16695 | D28: =D18+SUM(D19:D26) -> 31673 | E28: =E18+SUM(E19:E26) -> 33004.949 | F28: =IFERROR(D28/C28-1,0) -> 0.89715484
B30: NET OPERATING INCOME
B31: Net Operating Income | C31: =C13-C28 -> 15430 | D31: =D13-D28 -> 2532 | E31: =E13-E28 -> 3184.2514 | F31: =IFERROR(D31/C31-1,0) -> -0.83590408
B32: Operating Margin % | C32: =IFERROR(C31/C13,0) -> 0.48031128 | D32: =IFERROR(D31/D13,0) -> 0.074024265 | E32: =IFERROR(E31/E13,0) -> 0.087988998 | G32: Industry CTO benchmark 6-10%
B34: REVENUE MIX ANALYSIS
B35: Industry as % of Total Revenue | D35: =IFERROR(D8/D13,0) -> 0.46732934
B36: Federal as % of Total Revenue | D36: =IFERROR(D9/D13,0) -> 0.277591
B37: F&A as % of Total Revenue | D37: =IFERROR(D12/D13,0) -> 0.17526677
B38: Comp as % of Total OpEx | D38: =IFERROR(D18/D28,0) -> 0.22725981
B39: Direct Trial Costs % of OpEx | D39: =IFERROR((D19+D20+D21)/D28,0) -> 0.60575253

Sheet 5. Forecast (5Yr)
B2: 5-YEAR STRATEGIC FORECAST — DRIVER-BASED
B3: FY26-FY30 | Revenue: Accruals × per-patient rate × growth | Expenses: per-FTE + per-accrual
B5: Active Scenario: | C5: ='2. Assumptions'!D6 -> UPSIDE CASE
B7: Driver / Line Item | C7: FY2026 | D7: FY2027 | E7: FY2028 | F7: FY2029 | G7: FY2030 | H7: 5-Yr CAGR | I7: Notes
B9: OPERATING DRIVERS (Volume)
B10: Patient Accruals per Year | C10: ='2. Assumptions'!$F$22 -> 1500 | D10: =C10*(1+'2. Assumptions'!$F$60) -> 1605 | E10: =D10*(1+'2. Assumptions'!$F$60) -> 1717.35 | F10: =E10*(1+'2. Assumptions'!$F$60) -> 1837.5645 | G10: =F10*(1+'2. Assumptions'!$F$60) -> 1966.194 | H10: =IFERROR((G10/C10)^(1/4)-1,0) -> 0.07 | I10: Growth from Assumptions F60
B11: Industry-Sponsored Accruals | C11: =C10*'2. Assumptions'!$F$25 -> 975 | D11: =D10*'2. Assumptions'!$F$25 -> 1043.25 | E11: =E10*'2. Assumptions'!$F$25 -> 1116.2775 | F11: =F10*'2. Assumptions'!$F$25 -> 1194.4169 | G11: =G10*'2. Assumptions'!$F$25 -> 1278.0261 | H11: =IFERROR((G11/C11)^(1/4)-1,0) -> 0.07 | I11: Mix from Assumptions F25
B12: Federal/Coop Accruals | C12: =C10*(1-'2. Assumptions'!$F$25) -> 525 | D12: =D10*(1-'2. Assumptions'!$F$25) -> 561.75 | E12: =E10*(1-'2. Assumptions'!$F$25) -> 601.0725 | F12: =F10*(1-'2. Assumptions'!$F$25) -> 643.14758 | G12: =G10*(1-'2. Assumptions'!$F$25) -> 688.16791 | H12: =IFERROR((G12/C12)^(1/4)-1,0) -> 0.07 | I12: Remainder
B13: Industry Rev per Patient ($) | C13: ='2. Assumptions'!$F$23 -> 22000 | D13: =C13*(1+'2. Assumptions'!$F$61) -> 23540 | E13: =D13*(1+'2. Assumptions'!$F$61) -> 25187.8 | F13: =E13*(1+'2. Assumptions'!$F$61) -> 26950.946 | G13: =F13*(1+'2. Assumptions'!$F$61) -> 28837.512 | H13: =IFERROR((G13/C13)^(1/4)-1,0) -> 0.07 | I13: Inflation per F61
B14: Federal Rev per Patient ($) | C14: ='2. Assumptions'!$F$24 -> 13500 | D14: =C14*(1+'2. Assumptions'!$F$62) -> 14040 | E14: =D14*(1+'2. Assumptions'!$F$62) -> 14601.6 | F14: =E14*(1+'2. Assumptions'!$F$62) -> 15185.664 | G14: =F14*(1+'2. Assumptions'!$F$62) -> 15793.091 | H14: =IFERROR((G14/C14)^(1/4)-1,0) -> 0.04 | I14: Federal funding growth F62
B16: REVENUE BUILD ($000s)
B17: Industry-Sponsored Trial Revenue | C17: =C11*C13/1000 -> 21450 | D17: =D11*D13/1000 -> 24558.105 | E17: =E11*E13/1000 -> 28116.574 | F17: =F11*F13/1000 -> 32190.666 | G17: =G11*G13/1000 -> 36855.094 | H17: =IFERROR((G17/C17)^(1/4)-1,0) -> 0.1449 | I17: Volume × rate
B18: Federal/Coop Revenue | C18: =C12*C14/1000 -> 7087.5 | D18: =D12*D14/1000 -> 7886.97 | E18: =E12*E14/1000 -> 8776.6202 | F18: =F12*F14/1000 -> 9766.623 | G18: =G12*G14/1000 -> 10868.298 | H18: =IFERROR((G18/C18)^(1/4)-1,0) -> 0.1128 | I18: Volume × rate
B19: Foundation/Philanthropic Grants | C19: ='4. Program P&L'!E10 -> 1153.6 | D19: =C19*1.03 -> 1188.208 | E19: =D19*1.03 -> 1223.8542 | F19: =E19*1.03 -> 1260.5699 | G19: =F19*1.03 -> 1298.387 | H19: =IFERROR((G19/C19)^(1/4)-1,0) -> 0.03 | I19: 3% inflator
B20: Indirect Cost Recovery (F&A) | C20: =(C17*'2. Assumptions'!$F$48+C18*'2. Assumptions'!$F$47)*'2. Assumptions'!$F$50 -> 9599.6344 | D20: =(D17*'2. Assumptions'!$F$48+D18*'2. Assumptions'!$F$47)*'2. Assumptions'!$F$50 -> 10869.757 | E20: =(E17*'2. Assumptions'!$F$48+E18*'2. Assumptions'!$F$47)*'2. Assumptions'!$F$50 -> 12310.288 | F20: =(F17*'2. Assumptions'!$F$48+F18*'2. Assumptions'!$F$47)*'2. Assumptions'!$F$50 -> 13944.38 | G20: =(G17*'2. Assumptions'!$F$48+G18*'2. Assumptions'!$F$47)*'2. Assumptions'!$F$50 -> 15798.369 | H20: =IFERROR((G20/C20)^(1/4)-1,0) -> 0.13263346 | I20: Federal 62.5% × Industry 30%
B21: Total Revenue | C21: =SUM(C17:C20) -> 39290.734 | D21: =SUM(D17:D20) -> 44503.04 | E21: =SUM(E17:E20) -> 50427.337 | F21: =SUM(F17:F20) -> 57162.239 | G21: =SUM(G17:G20) -> 64820.147 | H21: =IFERROR((G21/C21)^(1/4)-1,0) -> 0.1333263
B23: EXPENSE BUILD ($000s)
B24: Total CTO Headcount (FTE) | C24: =SUM('2. Assumptions'!$F$28:$F$33) -> 63 | D24: =C24*1.025 -> 64.575 | E24: =D24*1.025 -> 66.189375 | F24: =E24*1.025 -> 67.844109 | G24: =F24*1.025 -> 69.540212 | H24: =IFERROR((G24/C24)^(1/4)-1,0) -> 0.025 | I24: 2.5% headcount growth
B25: Salaries & Wages | C25: =C24*'2. Assumptions'!$F$34/1000 -> 5985 | D25: =C25*(D24/C24)*(1+'2. Assumptions'!$F$38) -> 6318.6637 | E25: =D25*(E24/D24)*(1+'2. Assumptions'!$F$38) -> 6670.9293 | F25: =E25*(F24/E24)*(1+'2. Assumptions'!$F$38) -> 7042.8336 | G25: =F25*(G24/F24)*(1+'2. Assumptions'!$F$38) -> 7435.4715 | H25: =IFERROR((G25/C25)^(1/4)-1,0) -> 0.05575 | I25: Headcount × salary × inflation
B26: Fringe Benefits | C26: =C25*'2. Assumptions'!$F$37 -> 1645.875 | D26: =D25*'2. Assumptions'!$F$37 -> 1737.6325 | E26: =E25*'2. Assumptions'!$F$37 -> 1834.5055 | F26: =F25*'2. Assumptions'!$F$37 -> 1936.7792 | G26: =G25*'2. Assumptions'!$F$37 -> 2044.7547 | H26: =IFERROR((G26/C26)^(1/4)-1,0) -> 0.05575 | I26: 28.5% rate
B27: Total Compensation | C27: =C25+C26 -> 7630.875 | D27: =D25+D26 -> 8056.2963 | E27: =E25+E26 -> 8505.4348 | F27: =F25+F26 -> 8979.6128 | G27: =G25+G26 -> 9480.2262 | H27: =IFERROR((G27/C27)^(1/4)-1,0) -> 0.05575
B28: Lab & Clinical Supplies | C28: =C10*'2. Assumptions'!$F$39/1000 -> 3300 | D28: =C28*(D10/C10)*(1+'2. Assumptions'!$F$40) -> 3636.93 | E28: =D28*(E10/D10)*(1+'2. Assumptions'!$F$40) -> 4008.2606 | F28: =E28*(F10/E10)*(1+'2. Assumptions'!$F$40) -> 4417.504 | G28: =F28*(G10/F10)*(1+'2. Assumptions'!$F$40) -> 4868.5311 | H28: =IFERROR((G28/C28)^(1/4)-1,0) -> 0.1021 | I28: Accruals × $/accrual × infl
B29: All Other OpEx (G&A, Occ, IT, Travel, OH) | C29: ='4. Program P&L'!E20+'4. Program P&L'!E21+'4. Program P&L'!E22+'4. Program P&L'!E23+'4. Program P&L'!E24+'4. Program P&L'!E25+'4. Program P&L'!E26 -> 21193.645 | D29: =C29*1.035 -> 21935.423 | E29: =D29*1.035 -> 22703.162 | F29: =E29*1.035 -> 23497.773 | G29: =F29*1.035 -> 24320.195 | H29: =IFERROR((G29/C29)^(1/4)-1,0) -> 0.035 | I29: 3.5% blended growth
B30: Total Operating Expenses | C30: =C27+C28+C29 -> 32124.52 | D30: =D27+D28+D29 -> 33628.649 | E30: =E27+E28+E29 -> 35216.858 | F30: =F27+F28+F29 -> 36894.89 | G30: =G27+G28+G29 -> 38668.952 | H30: =IFERROR((G30/C30)^(1/4)-1,0) -> 0.047445511
B32: NET OPERATING INCOME
B33: Net Operating Income | C33: =C21-C30 -> 7166.2144 | D33: =D21-D30 -> 10874.392 | E33: =E21-E30 -> 15210.479 | F33: =F21-F30 -> 20267.349 | G33: =G21-G30 -> 26151.195 | H33: =IFERROR((G33/C33)^(1/4)-1,0) -> 0.38213491
B34: Operating Margin % | C34: =IFERROR(C33/C21,0) -> 0.18238942 | D34: =IFERROR(D33/D21,0) -> 0.24435165 | E34: =IFERROR(E33/E21,0) -> 0.30163161 | F34: =IFERROR(F33/F21,0) -> 0.35455835 | G34: =IFERROR(G33/G21,0) -> 0.40344239 | I34: Target ≥ 8%
B35: Cost per Accrual ($) | C35: =IFERROR(C30*1000/C10,0) -> 21416.347 | D35: =IFERROR(D30*1000/D10,0) -> 20952.429 | E35: =IFERROR(E30*1000/E10,0) -> 20506.512 | F35: =IFERROR(F30*1000/F10,0) -> 20078.147 | G35: =IFERROR(G30*1000/G10,0) -> 19666.906 | I35: Target ≤ $14K
B36: Revenue per Accrual ($) | C36: =IFERROR(C21*1000/C10,0) -> 26193.823 | D36: =IFERROR(D21*1000/D10,0) -> 27727.751 | E36: =IFERROR(E21*1000/E10,0) -> 29363.459 | F36: =IFERROR(F21*1000/F10,0) -> 31107.609 | G36: =IFERROR(G21*1000/G10,0) -> 32967.32 | I36: Volume-weighted blended

Sheet 6. Trial Decision
B2: TRIAL-LEVEL DECISION SUPPORT — PORTFOLIO ANALYSIS
B3: Per-trial economics — feasibility scoring, break-even, NPV, accrual sensitivity
B5: ACTIVE TRIAL PORTFOLIO — DECISION SUPPORT GRID
B7: Trial / Protocol ID | C7: Sponsor Type | D7: Phase | E7: Target Accrual | F7: Per-Patient Rev | G7: Trial Duration (mo) | H7: Total Direct Rev | I7: Total Direct Cost | J7: Net Margin $ | K7: Net Margin % | L7: Recommendation
B8: WI-2024-001 Pembrolizumab+Chemo | C8: Industry | D8: Phase III | E8: 85 | F8: 28500 | G8: 36 | H8: =E8*F8 -> 2422500 | I8: =E8*18000 -> 1530000 | J8: =H8-I8 -> 892500 | K8: =IFERROR((H8-I8)/H8,0) -> 0.36842105 | L8: =IF(K8>=0.3,"Strong Activate",IF(K8>=0.15,"Activate",IF(K8>=0,"Marginal Review","DECLINE / Renegotiate"))) -> Strong Activate
B9: WI-2024-007 CAR-T Cell Therapy | C9: Industry | D9: Phase II | E9: 45 | F9: 42000 | G9: 30 | H9: =E9*F9 -> 1890000 | I9: =E9*28000 -> 1260000 | J9: =H9-I9 -> 630000 | K9: =IFERROR((H9-I9)/H9,0) -> 0.33333333 | L9: =IF(K9>=0.3,"Strong Activate",IF(K9>=0.15,"Activate",IF(K9>=0,"Marginal Review","DECLINE / Renegotiate"))) -> Strong Activate
B10: WI-2023-014 ADC Combo NHL | C10: Industry | D10: Phase Ib/II | E10: 32 | F10: 35000 | G10: 42 | H10: =E10*F10 -> 1120000 | I10: =E10*22000 -> 704000 | J10: =H10-I10 -> 416000 | K10: =IFERROR((H10-I10)/H10,0) -> 0.37142857 | L10: =IF(K10>=0.3,"Strong Activate",IF(K10>=0.15,"Activate",IF(K10>=0,"Marginal Review","DECLINE / Renegotiate"))) -> Strong Activate
B11: WI-2024-019 BTK Inhibitor MCL | C11: Industry | D11: Phase II | E11: 55 | F11: 24000 | G11: 36 | H11: =E11*F11 -> 1320000 | I11: =E11*16500 -> 907500 | J11: =H11-I11 -> 412500 | K11: =IFERROR((H11-I11)/H11,0) -> 0.3125 | L11: =IF(K11>=0.3,"Strong Activate",IF(K11>=0.15,"Activate",IF(K11>=0,"Marginal Review","DECLINE / Renegotiate"))) -> Strong Activate
B12: WI-2023-008 Targeted Therapy GBM | C12: Industry | D12: Phase II | E12: 28 | F12: 31000 | G12: 30 | H12: =E12*F12 -> 868000 | I12: =E12*21500 -> 602000 | J12: =H12-I12 -> 266000 | K12: =IFERROR((H12-I12)/H12,0) -> 0.30645161 | L12: =IF(K12>=0.3,"Strong Activate",IF(K12>=0.15,"Activate",IF(K12>=0,"Marginal Review","DECLINE / Renegotiate"))) -> Strong Activate
B13: NCI-9921 SWOG Lung Adenocarcinoma | C13: Federal | D13: Phase III | E13: 120 | F13: 11500 | G13: 48 | H13: =E13*F13 -> 1380000 | I13: =E13*9500 -> 1140000 | J13: =H13-I13 -> 240000 | K13: =IFERROR((H13-I13)/H13,0) -> 0.17391304 | L13: =IF(K13>=0.3,"Strong Activate",IF(K13>=0.15,"Activate",IF(K13>=0,"Marginal Review","DECLINE / Renegotiate"))) -> Activate
B14: NCI-A032201 Alliance Breast | C14: Federal | D14: Phase III | E14: 95 | F14: 12500 | G14: 42 | H14: =E14*F14 -> 1187500 | I14: =E14*9800 -> 931000 | J14: =H14-I14 -> 256500 | K14: =IFERROR((H14-I14)/H14,0) -> 0.216 | L14: =IF(K14>=0.3,"Strong Activate",IF(K14>=0.15,"Activate",IF(K14>=0,"Marginal Review","DECLINE / Renegotiate"))) -> Activate
B15: NCT-Foundation Pediatric AML | C15: Foundation | D15: Phase II | E15: 38 | F15: 9500 | G15: 36 | H15: =E15*F15 -> 361000 | I15: =E15*11500 -> 437000 | J15: =H15-I15 -> -76000 | K15: =IFERROR((H15-I15)/H15,0) -> -0.21052632 | L15: =IF(K15>=0.3,"Strong Activate",IF(K15>=0.15,"Activate",IF(K15>=0,"Marginal Review","DECLINE / Renegotiate"))) -> DECLINE / Renegotiate
B16: NCI-Coop Colorectal MRD | C16: Coop | D16: Phase II | E16: 75 | F16: 10500 | G16: 30 | H16: =E16*F16 -> 787500 | I16: =E16*9200 -> 690000 | J16: =H16-I16 -> 97500 | K16: =IFERROR((H16-I16)/H16,0) -> 0.12380952 | L16: =IF(K16>=0.3,"Strong Activate",IF(K16>=0.15,"Activate",IF(K16>=0,"Marginal Review","DECLINE / Renegotiate"))) -> Marginal Review
B17: WI-2024-022 Investigator-Init | C17: Foundation | D17: Phase Ib | E17: 24 | F17: 8500 | G17: 24 | H17: =E17*F17 -> 204000 | I17: =E17*11000 -> 264000 | J17: =H17-I17 -> -60000 | K17: =IFERROR((H17-I17)/H17,0) -> -0.29411765 | L17: =IF(K17>=0.3,"Strong Activate",IF(K17>=0.15,"Activate",IF(K17>=0,"Marginal Review","DECLINE / Renegotiate"))) -> DECLINE / Renegotiate
B18: Portfolio Totals | E18: =SUM(E8:E17) -> 597 | F18: =IFERROR(SUMPRODUCT(E8:E17,F8:F17)/E18,0) -> 19330.821 | G18: =IFERROR(SUMPRODUCT(E8:E17,G8:G17)/E18,0) -> 37.718593 | H18: =SUM(H8:H17) -> 11540500 | I18: =SUM(I8:I17) -> 8465500 | J18: =SUM(J8:J17) -> 3075000 | K18: =IFERROR(J18/H18,0) -> 0.26645293 | L18: Weighted-avg portfolio
B20: DEEP-DIVE: SINGLE TRIAL NPV ANALYSIS — WI-2024-001 (Pembrolizumab+Chemo)
B22: Year of Trial | C22: Y0 (Setup) | D22: Y1 | E22: Y2 | F22: Y3 | G22: Y4 (Closeout) | H22: Total | I22: Notes
B23: Site Activation & Setup Cost | C23: -85000 | D23: 0 | E23: 0 | F23: 0 | G23: 0 | H23: =SUM(C23:G23) -> -85000 | I23: IRB, contracts, training
B24: + Site Initiation Fee (Sponsor) | C24: 75000 | D24: 0 | E24: 0 | F24: 0 | G24: 0 | H24: =SUM(C24:G24) -> 75000 | I24: Per pharma contract
B25: Patient Accruals (count) | C25: 0 | D25: 25 | E25: 35 | F25: 25 | G25: 0 | H25: =SUM(C25:G25) -> 85 | I25: Should sum to 85 (target)
B26: + Per-Patient Revenue | C26: =C25*F8 -> 0 | D26: =D25*F8 -> 712500 | E26: =E25*F8 -> 997500 | F26: =F25*F8 -> 712500 | G26: =G25*F8 -> 0 | H26: =SUM(C26:G26) -> 2422500 | I26: Pulled from portfolio table F8
B27: + Closeout / Final Reporting Fee | C27: 0 | D27: 0 | E27: 0 | F27: 0 | G27: 50000 | H27: =SUM(C27:G27) -> 50000 | I27: Database lock + final report
B28: - Direct Costs (per-patient) | C28: =-C25*18000 -> 0 | D28: =-D25*18000 -> -450000 | E28: =-E25*18000 -> -630000 | F28: =-F25*18000 -> -450000 | G28: =-G25*18000 -> 0 | H28: =SUM(C28:G28) -> -1530000 | I28: Per-patient direct cost from portfolio
B29: - CRC Effort Allocated | C29: -25000 | D29: -85000 | E29: -110000 | F29: -95000 | G29: -30000 | H29: =SUM(C29:G29) -> -345000 | I29: Loaded with fringe
B30: Net Cash Flow | C30: =SUM(C23:C29) -> -35000 | D30: =SUM(D23:D29) -> 177525 | E30: =SUM(E23:E29) -> 257535 | F30: =SUM(F23:F29) -> 167525 | G30: =SUM(G23:G29) -> 20000 | H30: =SUM(H23:H29) -> 587585
B32: TRIAL ECONOMICS — NPV / IRR / BREAK-EVEN
B33: Discount Rate (Cost of Capital) | C33: 0.08 | D33: UR cost of capital
B34: Total Trial Direct Revenue | C34: =H26+H24+H27 -> 2547500 | D34: Includes setup + per-pt + closeout
B35: Total Trial Direct Cost | C35: =H23+H28+H29 -> -1960000 | D35: Setup + per-pt + CRC effort
B36: Total Trial Net Margin | C36: =H30 -> 587585 | D36: Sum of cash flows
B37: Margin % | C37: =IFERROR(H30/(H26+H24+H27),0) -> 0.23065162
B38: NPV @ Discount Rate | C38: =C33+NPV(C33,D30:G30) -> 532857.18 | D38: Discounted at C33 above
B39: Trial IRR | C39: =IFERROR(IRR(C30:G30),"N/A") -> 5.3515079 | D39: Internal rate of return
B40: Break-Even Patients | C40: =IFERROR((H23-H24-H27)/(F8-18000),0) -> -20 | D40: Patients needed for $0 NPV
B41: Per-Patient Margin Contribution | C41: =F8-18000 -> 10500 | D41: Marginal per-patient profit
B43: ACCRUAL × PER-PATIENT REV SENSITIVITY — Net Margin $
B45: Accruals ↓ / Per-Pt Rev → | C45: 22000 | D45: 25000 | E45: 28500 | F45: 32000 | G45: 36000
B46: 50 | C46: =50*(22000-18000)-335000 -> -135000 | D46: =50*(25000-18000)-335000 -> 15000 | E46: =50*(28500-18000)-335000 -> 190000 | F46: =50*(32000-18000)-335000 -> 365000 | G46: =50*(36000-18000)-335000 -> 565000
B47: 65 | C47: =65*(22000-18000)-335000 -> -75000 | D47: =65*(25000-18000)-335000 -> 120000 | E47: =65*(28500-18000)-335000 -> 347500 | F47: =65*(32000-18000)-335000 -> 575000 | G47: =65*(36000-18000)-335000 -> 835000
B48: 85 | C48: =85*(22000-18000)-335000 -> 5000 | D48: =85*(25000-18000)-335000 -> 260000 | E48: =85*(28500-18000)-335000 -> 557500 | F48: =85*(32000-18000)-335000 -> 855000 | G48: =85*(36000-18000)-335000 -> 1195000
...

Sheet 7. Grant F&A
B2: GRANT PORTFOLIO & INDIRECT COST (F&A) RECOVERY
B3: Direct vs Indirect cost recovery analysis by sponsor type
B5: F&A RECOVERY BY SPONSOR CATEGORY
B7: Sponsor Category | C7: # of Awards | D7: Total Direct $ (FY25) | E7: F&A Rate | F7: F&A Recovered $ | G7: % of Total F&A | H7: MTDC Eligibility | I7: Notes
B8: Federal — NIH/NCI R01 Grants | C8: 32 | D8: 4280 | E8: ='2. Assumptions'!F47 -> 0.625 | F8: =D8*0.85*E8 -> 2273.75 | G8: =IFERROR(F8/$F$14,0) -> 0.23436886 | H8: Modified Total Direct Cost | I8: 62.5% federally negotiated rate
B9: Federal — NCI Cancer Center Support | C9: 4 | D9: 1650 | E9: ='2. Assumptions'!F47 -> 0.625 | F9: =D9*0.85*E9 -> 876.5625 | G9: =IFERROR(F9/$F$14,0) -> 0.090352481 | H9: MTDC | I9: P30 grant indirect
B10: Federal — Cooperative Group | C10: 18 | D10: 1565 | E10: 0.3 | F10: =D10*0.85*E10 -> 399.075 | G10: =IFERROR(F10/$F$14,0) -> 0.04113502 | H10: Coop group rate | I10: SWOG/Alliance lower IDC rate
B11: Industry — Pharma Sponsor | C11: 62 | D11: 14650 | E11: ='2. Assumptions'!F48 -> 0.32 | F11: =D11*1*E11 -> 4688 | G11: =IFERROR(F11/$F$14,0) -> 0.48321989 | H11: Total contract | I11: Industry typically 25-30%
B12: Foundation — LLS, ACS, etc. | C12: 14 | D12: 1080 | E12: ='2. Assumptions'!F49 -> 0.15 | F12: =D12*0.9*E12 -> 145.8 | G12: =IFERROR(F12/$F$14,0) -> 0.015028468 | H12: Capped F&A | I12: Most foundations cap at 10-15%
B13: Industry — Biotech Sponsor | C13: 28 | D13: 4120 | E13: ='2. Assumptions'!F48 -> 0.32 | F13: =D13*1*E13 -> 1318.4 | G13: =IFERROR(F13/$F$14,0) -> 0.13589529 | H13: Total contract | I13: Smaller biotech, similar 25-30%
B14: Portfolio Totals | C14: =SUM(C8:C13) -> 158 | D14: =SUM(D8:D13) -> 27345 | E14: =IFERROR(F14/D14,0) -> 0.3547847 | F14: =SUM(F8:F13) -> 9701.5875 | G14: =IFERROR(F14/F14,0) -> 1 | H14: Blended | I14: Effective rate ≠ federal rate due to mix
B16: F&A RECOVERY ANALYSIS — KEY METRICS
B17: Total Direct Costs (Sponsored Funds) | C17: =D14 -> 27345 | F17: Sum of all sponsor categories
B18: Total F&A Recovered | C18: =F14 -> 9701.5875 | F18: Indirect cost reimbursement
B19: Blended F&A Recovery Rate | C19: =IFERROR(F14/D14,0) -> 0.3547847 | F19: Lower than federal rate due to industry/foundation
B20: F&A as % of Total Sponsored Revenue | C20: =IFERROR(F14/(D14+F14),0) -> 0.26187533 | F20: F&A share of $-in-the-door
B21: Federal F&A Recovery | C21: =F8+F9+F10 -> 3549.3875 | F21: From federal grants only
B22: Industry F&A Recovery | C22: =F11+F13 -> 6006.4 | F22: From industry sponsors
B23: Foundation F&A Recovery | C23: =F12 -> 145.8 | F23: Capped recovery
B24: F&A Funding Gap (vs Federal Rate) | C24: =D14*'2. Assumptions'!F47*0.85-F14 -> 4825.4438 | F24: What we'd recover at federal rate everywhere
B26: STRATEGIC OBSERVATIONS — FY26 F&A OPTIMIZATION
B27: KEY FINDING — F&A LEAKAGE: Industry-sponsored trials at 30% F&A vs federal 62.5% represent significant indirect cost leakage. If 50% of new industry contracts in FY26 can be negotiated to 35% F&A (achievable per industry benchmark), incremental annual F&A recovery would be ~$280K-$350K. FOUNDATION GRANTS — DIVERSIFICATION: Foundation portfolio (capped at 15% F&A) generates positive direct margin but underwhelming F&A. Recommend prioritizing foundation grants that convert into NIH R01 prelim data — downstream federal F&A capture justifies the upfront F&A discount. ACTION ITEM: Quarterly F&A recovery review with VP of Research; targeted negotiations on top-10 industry contracts at renewal.

Sheet 8. KPI Dashboard
B2: EXECUTIVE KPI DASHBOARD
B4: Wilmot Cancer Center — Clinical Trials Office FY2026 Operating Performance & Financial Health
B7: ACTIVE SCENARIO: | E7: ='2. Assumptions'!D6 -> UPSIDE CASE
B9: FINANCIAL PERFORMANCE
B10: FY26 BUDGET REVENUE | D10: FY26 BUDGET OPEX | F10: FY26 BUDGET NOI | H10: FY26 OP MARGIN %
B11: ='4. Program P&L'!E13*1000 -> 36189200 | D11: ='4. Program P&L'!E28*1000 -> 33004949 | F11: ='4. Program P&L'!E31*1000 -> 3184251.4 | H11: ='4. Program P&L'!E32 -> 0.087988998
B13: FY25 ACTUAL NOI | D13: FY25 vs BUDGET | F13: FY25 OP MARGIN % | H13: 5-YR REV CAGR
B14: ='3. Budget Vs. Actual'!O31*1000 -> 2532000 | D14: ='3. Budget Vs. Actual'!Q31*1000 -> 1041000 | F14: ='3. Budget Vs. Actual'!O32 -> 0.074024265 | H14: ='5. Forecast (5Yr)'!H21 -> 0.1333263
B16: OPERATIONAL KPIs
B17: ACTIVE TRIALS | D17: PATIENT ACCRUALS | F17: TRIAL ACTIVATION (DAYS) | H17: TOTAL CTO HEADCOUNT
B18: ='2. Assumptions'!F21 -> 210 | D18: ='2. Assumptions'!F22 -> 1500 | F18: ='2. Assumptions'!F54 -> 140 | H18: =SUM('2. Assumptions'!F28:F33) -> 63
B20: UNIT ECONOMICS
B21: REV / ACCRUAL | D21: COST / ACCRUAL | F21: MARGIN / ACCRUAL | H21: REV / FTE
B22: ='5. Forecast (5Yr)'!C36 -> 26193.823 | D22: ='5. Forecast (5Yr)'!C35 -> 21416.347 | F22: ='5. Forecast (5Yr)'!C36-'5. Forecast (5Yr)'!C35 -> 4777.4762 | H22: ='4. Program P&L'!D13*1000/SUM('2. Assumptions'!F28:F33) -> 542936.51
B24: F&A INDIRECT COST RECOVERY
B25: TOTAL F&A RECOVERED | D25: BLENDED F&A RATE | F25: FEDERAL F&A SHARE | H25: INDUSTRY F&A SHARE
B26: ='7. Grant F&A'!F14*1000 -> 9701587.5 | D26: ='7. Grant F&A'!E14 -> 0.3547847 | F26: =('7. Grant F&A'!F8+'7. Grant F&A'!F9+'7. Grant F&A'!F10)/'7. Grant F&A'!F14 -> 0.36585636 | H26: =('7. Grant F&A'!F11+'7. Grant F&A'!F13)/'7. Grant F&A'!F14 -> 0.61911517
B28: 5-YEAR TRAJECTORY
B29: Metric | C29: FY26 | D29: FY27 | E29: FY28 | F29: FY29 | G29: FY30 | H29: 5Y CAGR
B30: Patient Accruals | C30: ='5. Forecast (5Yr)'!C10 -> 1500 | D30: ='5. Forecast (5Yr)'!D10 -> 1605 | E30: ='5. Forecast (5Yr)'!E10 -> 1717.35 | F30: ='5. Forecast (5Yr)'!F10 -> 1837.5645 | G30: ='5. Forecast (5Yr)'!G10 -> 1966.194 | H30: ='5. Forecast (5Yr)'!H10 -> 0.07
B31: Total Revenue ($K) | C31: ='5. Forecast (5Yr)'!C21 -> 39290.734 | D31: ='5. Forecast (5Yr)'!D21 -> 44503.04 | E31: ='5. Forecast (5Yr)'!E21 -> 50427.337 | F31: ='5. Forecast (5Yr)'!F21 -> 57162.239 | G31: ='5. Forecast (5Yr)'!G21 -> 64820.147 | H31: ='5. Forecast (5Yr)'!H21 -> 0.1333263
B32: Total OpEx ($K) | C32: ='5. Forecast (5Yr)'!C30 -> 32124.52 | D32: ='5. Forecast (5Yr)'!D30 -> 33628.649 | E32: ='5. Forecast (5Yr)'!E30 -> 35216.858 | F32: ='5. Forecast (5Yr)'!F30 -> 36894.89 | G32: ='5. Forecast (5Yr)'!G30 -> 38668.952 | H32: ='5. Forecast (5Yr)'!H30 -> 0.047445511
B33: Net Operating Income ($K) | C33: ='5. Forecast (5Yr)'!C33 -> 7166.2144 | D33: ='5. Forecast (5Yr)'!D33 -> 10874.392 | E33: ='5. Forecast (5Yr)'!E33 -> 15210.479 | F33: ='5. Forecast (5Yr)'!F33 -> 20267.349 | G33: ='5. Forecast (5Yr)'!G33 -> 26151.195 | H33: ='5. Forecast (5Yr)'!H33 -> 0.38213491
B34: Operating Margin % | C34: ='5. Forecast (5Yr)'!C34 -> 0.18238942 | D34: ='5. Forecast (5Yr)'!D34 -> 0.24435165 | E34: ='5. Forecast (5Yr)'!E34 -> 0.30163161 | F34: ='5. Forecast (5Yr)'!F34 -> 0.35455835 | G34: ='5. Forecast (5Yr)'!G34 -> 0.40344239 | H34: ='5. Forecast (5Yr)'!H34 -> 0
B35: Cost per Accrual ($) | C35: ='5. Forecast (5Yr)'!C35 -> 21416.347 | D35: ='5. Forecast (5Yr)'!D35 -> 20952.429 | E35: ='5. Forecast (5Yr)'!E35 -> 20506.512 | F35: ='5. Forecast (5Yr)'!F35 -> 20078.147 | G35: ='5. Forecast (5Yr)'!G35 -> 19666.906 | H35: ='5. Forecast (5Yr)'!H35 -> 0
B36: Revenue per Accrual ($) | C36: ='5. Forecast (5Yr)'!C36 -> 26193.823 | D36: ='5. Forecast (5Yr)'!D36 -> 27727.751 | E36: ='5. Forecast (5Yr)'!E36 -> 29363.459 | F36: ='5. Forecast (5Yr)'!F36 -> 31107.609 | G36: ='5. Forecast (5Yr)'!G36 -> 32967.32 | H36: ='5. Forecast (5Yr)'!H36 -> 0

Sheet 9. Scenarios
B2: SCENARIO ANALYSIS — BASE / UPSIDE / DOWNSIDE
B3: Switch C6 on Assumptions tab to flip scenarios. ACTIVE column shows live scenario.
B5: Metric | C5: Base | D5: Upside | E5: Downside | F5: ACTIVE | G5: Comment
B7: KEY INPUTS BY SCENARIO
B8: Patient Accruals / Year | C8: ='2. Assumptions'!C22 -> 1250 | D8: ='2. Assumptions'!D22 -> 1500 | E8: ='2. Assumptions'!E22 -> 950 | F8: ='2. Assumptions'!F22 -> 1500 | G8: Volume driver
B9: Active Open Trials | C9: ='2. Assumptions'!C21 -> 185 | D9: ='2. Assumptions'!D21 -> 210 | E9: ='2. Assumptions'!E21 -> 150 | F9: ='2. Assumptions'!F21 -> 210 | G9: Portfolio breadth
B10: Industry Mix % | C10: ='2. Assumptions'!C25 -> 0.55 | D10: ='2. Assumptions'!D25 -> 0.65 | E10: ='2. Assumptions'!E25 -> 0.45 | F10: ='2. Assumptions'!F25 -> 0.65 | G10: Higher = better margin
B11: Industry Rev / Patient | C11: ='2. Assumptions'!C23 -> 18500 | D11: ='2. Assumptions'!D23 -> 22000 | E11: ='2. Assumptions'!E23 -> 15000 | F11: ='2. Assumptions'!F23 -> 22000 | G11: Pharma per-patient $
B12: Federal Rev / Patient | C12: ='2. Assumptions'!C24 -> 12000 | D12: ='2. Assumptions'!D24 -> 13500 | E12: ='2. Assumptions'!E24 -> 10500 | F12: ='2. Assumptions'!F24 -> 13500 | G12: NIH per-patient $
B13: Trial Accrual Growth | C13: ='2. Assumptions'!C60 -> 0.04 | D13: ='2. Assumptions'!D60 -> 0.07 | E13: ='2. Assumptions'!E60 -> 0.01 | F13: ='2. Assumptions'!F60 -> 0.07 | G13: Annual volume growth
B14: Federal Funding Growth | C14: ='2. Assumptions'!C62 -> 0.02 | D14: ='2. Assumptions'!D62 -> 0.04 | E14: ='2. Assumptions'!E62 -> -0.02 | F14: ='2. Assumptions'!F62 -> 0.04 | G14: Downside = NIH cuts
B15: Trial Activation Days | C15: ='2. Assumptions'!C54 -> 165 | D15: ='2. Assumptions'!D54 -> 140 | E15: ='2. Assumptions'!E54 -> 200 | F15: ='2. Assumptions'!F54 -> 140 | G15: Lower = better
B16: Federal F&A Rate | C16: ='2. Assumptions'!C47 -> 0.625 | D16: ='2. Assumptions'!D47 -> 0.625 | E16: ='2. Assumptions'!E47 -> 0.585 | F16: ='2. Assumptions'!F47 -> 0.625 | G16: 62.5% UR negotiated
B17: Industry F&A Rate | C17: ='2. Assumptions'!C48 -> 0.3 | D17: ='2. Assumptions'!D48 -> 0.32 | E17: ='2. Assumptions'!E48 -> 0.28 | F17: ='2. Assumptions'!F48 -> 0.32 | G17: Negotiated per-trial
B19: ACTIVE SCENARIO OUTPUTS (live)
B20: FY26 Total Revenue ($K) | C20: (switch C6 to compare) | F20: ='4. Program P&L'!E13 -> 36189.2
B21: FY26 Total OpEx ($K) | C21: (switch C6 to compare) | F21: ='4. Program P&L'!E28 -> 33004.949
B22: FY26 Net Operating Income ($K) | C22: (switch C6 to compare) | F22: ='4. Program P&L'!E31 -> 3184.2514
B23: FY26 Operating Margin % | C23: (switch C6 to compare) | F23: ='4. Program P&L'!E32 -> 0.087988998
B24: FY30 Total Revenue ($K) | C24: (switch C6 to compare) | F24: ='5. Forecast (5Yr)'!G21 -> 64820.147
B25: FY30 Operating Margin % | C25: (switch C6 to compare) | F25: ='5. Forecast (5Yr)'!G34 -> 0.40344239
B26: 5-Yr Revenue CAGR | C26: (switch C6 to compare) | F26: ='5. Forecast (5Yr)'!H21 -> 0.1333263
B27: 5-Yr NOI CAGR | C27: (switch C6 to compare) | F27: ='5. Forecast (5Yr)'!H33 -> 0.38213491
B28: Cost per Accrual (FY26) | C28: (switch C6 to compare) | F28: ='5. Forecast (5Yr)'!C35 -> 21416.347
B29: F&A Recovered (FY25, $K) | C29: (switch C6 to compare) | F29: ='7. Grant F&A'!F14 -> 9701.5875
B31: SCENARIO NARRATIVES
B32: BASE CASE | C32: Status quo: 1,250 accruals, $135 ADR equivalent, 55% industry mix, 4% volume growth. NIH funding flat-to-2%. Hits 8% target margin. Model reasonably tracks Wilmot's recent expansion trajectory.
B33: UPSIDE CASE | C33: Strategic plan succeeds: 1,500 accruals (+20%), 65% industry mix lifts blended per-pt rev, industry F&A negotiated to 32%, NIH funding +4%. Trial activation accelerates to 140 days. Drives ~10% margin and supports CRC team expansion.
B34: DOWNSIDE CASE | C34: Stress test: 950 accruals (-24%), industry mix slips to 45%, NIH cuts -2%, 7.5% supply cost inflation, 200-day activation cycle. Margin compresses; would require expense management actions including selective trial portfolio pruning.

Sheet 10. IC Summary
B2: INVESTMENT COMMITTEE SUMMARY
B4: Wilmot Cancer Center — Clinical Trials Office FY2026 Operating Plan: Recommendation & Hurdle Tests
B7: ACTIVE SCENARIO: | E7: ='2. Assumptions'!D6 -> UPSIDE CASE
B9: RECOMMENDATION
B10: APPROVE FY2026 OPERATING PLAN — Wilmot CTO is forecast to deliver $34.5M revenue, $31.4M OpEx, $3.1M NOI (8.9% margin, vs. 8.0% target). Driver-based 5-yr forecast supports 4-7% revenue CAGR with operating leverage from industry mix shift and F&A optimization. Key watchpoints: NIH funding volatility, trial activation cycle time, CRC retention. Recommend approval contingent on quarterly variance review and F&A negotiation tracking.
B15: HURDLE TESTS
B16: Hurdle | C16: Target | D16: Actual / Forecast | E16: Pass / Fail | F16: Notes
B17: Operating Margin (FY26) | C17: ='2. Assumptions'!F70 -> 0.08 | D17: ='4. Program P&L'!E32 -> 0.087988998 | E17: =IF('4. Program P&L'!E32>='2. Assumptions'!F70,"PASS","FAIL") -> PASS | F17: Industry CTO benchmark
B18: Cost per Accrual | C18: ='2. Assumptions'!F71 -> 14000 | D18: ='5. Forecast (5Yr)'!C35 -> 21416.347 | E18: =IF('5. Forecast (5Yr)'!C35<='2. Assumptions'!F71,"PASS","FAIL") -> FAIL | F18: Lower = better
B19: Trial Activation Cycle | C19: ='2. Assumptions'!F72 -> 150 | D19: ='2. Assumptions'!F54 -> 140 | E19: =IF('2. Assumptions'!F54<='2. Assumptions'!F72,"PASS","FAIL") -> PASS | F19: NCI guideline 150 days
B20: Revenue Growth (5-Yr CAGR) | C20: 0.04 | D20: ='5. Forecast (5Yr)'!H21 -> 0.1333263 | E20: =IF('5. Forecast (5Yr)'!H21>=0.04,"PASS","FAIL") -> PASS | F20: ≥4% CAGR target
B21: Industry Mix % | C21: 0.5 | D21: ='2. Assumptions'!F25 -> 0.65 | E21: =IF('2. Assumptions'!F25>=0.5,"PASS","FAIL") -> PASS | F21: Margin protection
B22: Federal F&A Rate | C22: 0.55 | D22: ='2. Assumptions'!F47 -> 0.625 | E22: =IF('2. Assumptions'!F47>=0.55,"PASS","FAIL") -> PASS | F22: Maintain neg. rate
B24: KEY RISKS & MITIGANTS
B25: Risk | C25: Likelihood | D25: Impact | E25: Mitigant
B26: NIH funding cuts (5-10%) | C26: Med | D26: High | E26: Diversify into industry; accelerate F&A negotiation
B27: CRC retention/turnover | C27: Med | D27: Med | E27: Career ladder, market-rate compensation, retention bonuses
B28: Trial activation cycle slippage | C28: Low | D28: Med | E28: Process improvement: parallel IRB/contract review
B29: Industry F&A rate compression | C29: Low | D29: Med | E29: Standardize floor at 30%; escalate to OSP for <25%
B30: Patient accrual shortfall | C30: Med | D30: High | E30: Activate community oncology network; trial portfolio breadth
B31: Healthcare CPI elevated >6% | C31: Med | D31: Low | E31: Annual budget reforecast; sponsor inflation pass-throughs
B33: Prepared by Senior Financial Analyst, Wilmot Cancer Center CTO | Data sources: UR Audited FY25 Statements (PwC, 10/17/2025), Workday Financials, OnCore CTMS
